<?xml version="1.0" ?>
<!-- =================================================================================== -->
<!-- |    This document was autogenerated by xacro from urdf/mobile_base.xacro         | -->
<!-- |    EDITING THIS FILE BY HAND IS NOT RECOMMENDED                                 | -->
<!-- =================================================================================== -->
<robot name="mobile_base" xmlns:xacro="http://www.ros.org/wiki/xacro">
  <!-- fictitious center point on ground and between wheels for navigation -->
  <link name="base_footprint">
    <visual>
      <geometry>
        <box size="0.001 0.001 0.001"/>
      </geometry>
      <origin rpy="0 0 0" xyz="0 0 0"/>
      <material name="black">
        <color rgba="0 0 0 1"/>
      </material>
    </visual>
  </link>
  <link name="base_link">
    <visual>
      <geometry>
        <box size="0.001 0.001 0.001"/>
      </geometry>
      <material name="black">
        <color rgba="0 0 0 1"/>
      </material>
    </visual>
  </link>
  <joint name="base_footprint_joint" type="fixed">
    <parent link="base_footprint"/>
    <child link="base_link"/>
    <origin rpy="0 0 0" xyz="0 0 0.0328"/>
  </joint>
  <!-- Base platform -->
  <link name="platform">
    <visual>
      <geometry>
        <box size="0.2032 0.2286 0.0064"/>
      </geometry>
      <material name="white">
        <color rgba="1 1 1 1"/>
      </material>
    </visual>
  </link>
  <joint name="platform_joint" type="fixed">
    <parent link="base_link"/>
    <child link="platform"/>
    <origin rpy="0 0 0" xyz="0 0 0.0178"/>
  </joint>
  <!-- Differential Drive Wheels -->
  <link name="wheel_right">
    <visual>
      <geometry>
        <cylinder length="0.0267" radius="0.0328"/>
      </geometry>
      <origin rpy="1.5707963268 0 0"/>
      <material name="black">
        <color rgba="0 0 0 1"/>
      </material>
    </visual>
  </link>
  <link name="wheel_left">
    <visual>
      <geometry>
        <cylinder length="0.0267" radius="0.0328"/>
      </geometry>
      <origin rpy="-1.5707963268 0 0"/>
      <material name="black">
        <color rgba="0 0 0 1"/>
      </material>
    </visual>
  </link>
  <joint name="wheel_left_joint" type="continuous">
    <parent link="base_link"/>
    <child link="wheel_left"/>
    <axis xyz="0 1 0"/>
    <origin rpy="0 0 0" xyz="0 0.13015 0"/>
  </joint>
  <joint name="wheel_right_joint" type="continuous">
    <parent link="base_link"/>
    <child link="wheel_right"/>
    <axis xyz="0 1 0"/>
    <origin rpy="0 0 0" xyz="0 -0.13015 0"/>
  </joint>
  <!-- Sensor Array -->
  <link name="sonar_left">
    <visual>
      <geometry>
        <box size=".0015 0.0046 0.0021"/>
      </geometry>
    </visual>
  </link>
  <link name="sonar_right">
    <visual>
      <geometry>
        <box size=".0015 0.0046 0.0021"/>
      </geometry>
    </visual>
  </link>
  <link name="ir_left">
    <visual>
      <geometry>
        <box size=".0014 0.0030 0.0013"/>
      </geometry>
    </visual>
  </link>
  <link name="ir_center">
    <visual>
      <geometry>
        <box size=".0014 0.0030 0.0013"/>
      </geometry>
    </visual>
  </link>
  <link name="ir_right">
    <visual>
      <geometry>
        <box size=".0014 0.0030 0.0013"/>
      </geometry>
    </visual>
  </link>
  <joint name="sonar_right_joint" type="fixed">
    <parent link="platform"/>
    <child link="sonar_right"/>
    <origin rpy="0 0 -0.35" xyz="0.0936 -0.0635 0.005"/>
  </joint>
  <joint name="sonar_left_joint" type="fixed">
    <parent link="platform"/>
    <child link="sonar_left"/>
    <origin rpy="0 0 0.35" xyz="0.0936 0.0635 0.005"/>
  </joint>
  <joint name="ir_right_joint" type="fixed">
    <parent link="platform"/>
    <child link="ir_right"/>
    <origin rpy="0 0 -0.7" xyz="0.0766 -0.125 0.005"/>
  </joint>
  <joint name="ir_center_joint" type="fixed">
    <parent link="platform"/>
    <child link="ir_center"/>
    <origin rpy="0 0 0" xyz="0.1023 0 0.005"/>
  </joint>
  <joint name="ir_left_joint" type="fixed">
    <parent link="platform"/>
    <child link="ir_left"/>
    <origin rpy="0 0 0.7" xyz="0.0766 0.125 0.005"/>
  </joint>
  <link name="sonar_left_depth_frame">
    <inertial>
      <mass value="0.0001"/>
      <origin xyz="0 0 0"/>
      <inertia ixx="0.0001" ixy="0.0" ixz="0.0" iyy="0.0001" iyz="0.0" izz="0.0001"/>
    </inertial>
  </link>
  <link name="sonar_right_depth_frame">
    <inertial>
      <mass value="0.0001"/>
      <origin xyz="0 0 0"/>
      <inertia ixx="0.0001" ixy="0.0" ixz="0.0" iyy="0.0001" iyz="0.0" izz="0.0001"/>
    </inertial>
  </link>
  <link name="ir_left_depth_frame">
    <inertial>
      <mass value="0.0001"/>
      <origin xyz="0 0 0"/>
      <inertia ixx="0.0001" ixy="0.0" ixz="0.0" iyy="0.0001" iyz="0.0" izz="0.0001"/>
    </inertial>
  </link>
  <link name="ir_center_depth_frame">
    <inertial>
      <mass value="0.0001"/>
      <origin xyz="0 0 0"/>
      <inertia ixx="0.0001" ixy="0.0" ixz="0.0" iyy="0.0001" iyz="0.0" izz="0.0001"/>
    </inertial>
  </link>
  <link name="ir_right_depth_frame">
    <inertial>
      <mass value="0.0001"/>
      <origin xyz="0 0 0"/>
      <inertia ixx="0.0001" ixy="0.0" ixz="0.0" iyy="0.0001" iyz="0.0" izz="0.0001"/>
    </inertial>
  </link>
  <joint name="sonar_left_depth_joint" type="fixed">
    <origin rpy="0 0 0" xyz="0 0.015 0"/>
    <parent link="sonar_left"/>
    <child link="sonar_left_depth_frame"/>
  </joint>
  <joint name="sonar_right_depth_joint" type="fixed">
    <origin rpy="0 0 0" xyz="0 0.015 0"/>
    <parent link="sonar_right"/>
    <child link="sonar_right_depth_frame"/>
  </joint>
  <joint name="ir_left_depth_joint" type="fixed">
    <origin rpy="0 0 0" xyz="0 0.015 0"/>
    <parent link="ir_left"/>
    <child link="ir_left_depth_frame"/>
  </joint>
  <joint name="ir_center_depth_joint" type="fixed">
    <origin rpy="0 0 0" xyz="0 0.015 0"/>
    <parent link="ir_center"/>
    <child link="ir_center_depth_frame"/>
  </joint>
  <joint name="ir_right_depth_joint" type="fixed">
    <origin rpy="0 0 0" xyz="0 0.015 0"/>
    <parent link="ir_right"/>
    <child link="ir_right_depth_frame"/>
  </joint>
</robot>

