<?xml version="1.0" ?>
<!-- =================================================================================== -->
<!-- |    This document was autogenerated by xacro from mobile_base.xacro              | -->
<!-- |    EDITING THIS FILE BY HAND IS NOT RECOMMENDED                                 | -->
<!-- =================================================================================== -->
<robot name="mobile_base" xmlns:xacro="http://www.ros.org/wiki/xacro">
  <!-- fictitious center point on ground and between wheels for navigation -->
  <link name="base_footprint">
    <visual>
      <geometry>
        <box size="0.001 0.001 0.001"/>
      </geometry>
      <origin rpy="0 0 0" xyz="0 0 0"/>
      <material name="black">
        <color rgba="0 0 0 1"/>
      </material>
    </visual>
  </link>
  <link name="base_link">
    <visual>
      <geometry>
        <box size="0.001 0.001 0.001"/>
      </geometry>
      <material name="black">
        <color rgba="0 0 0 1"/>
      </material>
    </visual>
  </link>
  <link name="platform">
    <visual>
      <geometry>
        <box size="0.2032 0.2286 0.0064"/>
      </geometry>
      <material name="white">
        <color rgba="1 1 1 1"/>
      </material>
    </visual>
  </link>
  <link name="wheel_left">
    <visual>
      <geometry>
        <cylinder length="0.0267" radius="0.0328"/>
      </geometry>
      <origin rpy="1.5707963268 0 0"/>
      <material name="black">
        <color rgba="0 0 0 1"/>
      </material>
    </visual>
  </link>
  <link name="wheel_right">
    <visual>
      <geometry>
        <cylinder length="0.0267" radius="0.0328"/>
      </geometry>
      <origin rpy="-1.5707963268 0 0"/>
      <material name="black">
        <color rgba="0 0 0 1"/>
      </material>
    </visual>
  </link>
  <joint name="base_footprint_joint" type="fixed">
    <parent link="base_footprint"/>
    <child link="base_link"/>
    <origin rpy="0 0 0" xyz="0 0 0.0328"/>
  </joint>
  <joint name="platform_joint" type="fixed">
    <parent link="base_link"/>
    <child link="platform"/>
    <origin rpy="0 0 0" xyz="0 0 0.0178"/>
  </joint>
  <joint name="wheel_left_joint" type="continuous">
    <parent link="base_link"/>
    <child link="wheel_left"/>
    <axis xyz="0 1 0"/>
    <origin rpy="0 0 0" xyz="0 0.13015 0"/>
  </joint>
  <joint name="wheel_right_joint" type="continuous">
    <parent link="base_link"/>
    <child link="wheel_right"/>
    <axis xyz="0 1 0"/>
    <origin rpy="0 0 0" xyz="0 -0.13015 0"/>
  </joint>
</robot>

