<?xml version="1.0" ?>
<!-- =================================================================================== -->
<!-- |    This document was autogenerated by xacro from mower.xacro                    | -->
<!-- |    EDITING THIS FILE BY HAND IS NOT RECOMMENDED                                 | -->
<!-- =================================================================================== -->
<robot name="mower" xmlns:xacro="http://www.ros.org/wiki/xacro">
  <link name="base_link">
    <visual>
      <geometry>
        <box size="0.001 0.001 0.001"/>
      </geometry>
      <material name="black">
        <color rgba="0 0 0 1"/>
      </material>
    </visual>
  </link>
  <!-- Bot platform -->
  <link name="platform">
    <visual>
      <geometry>
        <box size="0.876 0.33 0.33"/>
      </geometry>
      <material name="white">
        <color rgba="1 1 1 1"/>
      </material>
    </visual>
  </link>
  <joint name="platform_joint" type="fixed">
    <parent link="base_link"/>
    <child link="platform"/>
    <origin rpy="0 0 0" xyz="0 0 0"/>
  </joint>
  <link name="platform_f">
    <visual>
      <geometry>
        <box size="0.432 0.622  0.33"/>
      </geometry>
      <material name="white"/>
    </visual>
  </link>
  <joint name="platform_f_joint" type="fixed">
    <parent link="base_link"/>
    <child link="platform_f"/>
    <origin xyz="0.238 0  0"/>
  </joint>
  <link name="platform_b">
    <visual>
      <geometry>
        <box size="0.14  0.483 0.33"/>
      </geometry>
      <material name="white"/>
    </visual>
  </link>
  <joint name="platform_b_joint" type="fixed">
    <parent link="base_link"/>
    <child link="platform_b"/>
    <origin xyz="-0.368 0 0"/>
  </joint>
  <link name="wheel_right">
    <visual>
      <geometry>
        <cylinder length="0.068" radius="0.121"/>
      </geometry>
      <origin rpy="1.57079632679 0 0"/>
      <material name="black">
        <color rgba="0 0 0 1"/>
      </material>
    </visual>
  </link>
  <link name="wheel_left">
    <visual>
      <geometry>
        <cylinder length="0.068" radius="0.121"/>
      </geometry>
      <origin rpy="-1.57079632679 0 0"/>
      <material name="black">
        <color rgba="0 0 0 1"/>
      </material>
    </visual>
  </link>
  <joint name="wheel_left_joint" type="continuous">
    <parent link="base_link"/>
    <child link="wheel_left"/>
    <axis xyz="0 1 0"/>
    <origin rpy="0 0 0" xyz="-0.146 0.2115 -0.069"/>
  </joint>
  <joint name="wheel_right_joint" type="continuous">
    <parent link="base_link"/>
    <child link="wheel_right"/>
    <axis xyz="0 1 0"/>
    <origin rpy="0 0 0" xyz="-0.146 -0.2115 -0.069"/>
  </joint>
  <!-- Front Wheel -->
  <link name="wheel_f">
    <visual>
      <geometry>
        <sphere radius="0.1"/>
      </geometry>
      <material name="black"/>
    </visual>
  </link>
  <joint name="wheel_f_joint" type="fixed">
    <parent link="base_link"/>
    <child link="wheel_f"/>
    <origin xyz="0.336 0 -0.09"/>
  </joint>
  <!-- GPS -->
  <link name="gps">
    <visual>
      <geometry>
        <box size="0.025 0.025 0.0125"/>
      </geometry>
      <material name="white"/>
    </visual>
  </link>
  <joint name="gps_joint" type="fixed">
    <parent link="base_link"/>
    <child link="gps"/>
    <origin xyz="0 0 .4"/>
  </joint>
</robot>

