<?xml version="1.0" ?>
<!-- =================================================================================== -->
<!-- |    This document was autogenerated by xacro from ../urdf/robot.xacro            | -->
<!-- |    EDITING THIS FILE BY HAND IS NOT RECOMMENDED                                 | -->
<!-- =================================================================================== -->
<robot name="blah" xmlns:xacro="http://www.ros.org/wiki/xacro">
  <link name="base_link">
    <visual>
      <geometry>
        <box size="0.001 0.001 0.001"/>
      </geometry>
      <material name="black">
        <color rgba="0 0 0 1"/>
      </material>
    </visual>
  </link>
  <!-- fictitious center point between wheels for navigation -->
  <!--
  <link name="base_link">
    <visual>
      <geometry>
        <box size="0.001 0.001 0.001"/>
      </geometry>
      <material name="black">
        <color rgba="0 0 0 1" />
      </material>
    </visual>
  </link>
-->
  <!-- Bot platforms -->
  <link name="platform_base">
    <visual>
      <geometry>
        <box size="0.2032 0.2286 0.0064"/>
      </geometry>
      <material name="white">
        <color rgba="1 1 1 1"/>
      </material>
    </visual>
  </link>
  <link name="platform_upper">
    <visual>
      <geometry>
        <box size="0.2032 0.2286 0.0064"/>
      </geometry>
      <material name="white">
        <color rgba="1 1 1 1"/>
      </material>
    </visual>
  </link>
  <joint name="platform_joint_base" type="fixed">
    <parent link="base_link"/>
    <child link="platform_base"/>
    <origin rpy="0 0 0" xyz="0 0 0.0178"/>
  </joint>
  <joint name="platform_joint_upper" type="fixed">
    <parent link="base_link"/>
    <child link="platform_upper"/>
    <origin rpy="0 0 0" xyz="0 0 0.0978"/>
  </joint>
  <!--
<link name="kinect_link">
  <visual>
    <geometry>
      <box size="0.064 0.121 0.0381" />
    </geometry>
    <material name="Blue" />
  </visual>
  <inertial>
      <mass value="0.0001" />
      <origin xyz="0 0 0" />
      <inertia ixx="0.0001" ixy="0.0" ixz="0.0"
               iyy="0.0001" iyz="0.0" 
               izz="0.0001" />
  </inertial>
</link>

<joint name="kinect_base_joint" type="fixed">
  <origin xyz="${platform_l / 2} 0 ${wheel_r + wheel_h_offset + 0.08}" rpy="0 0 0" />
  <parent link="base_link" />
  <child link="kinect_link" />
</joint>

<joint name="kinect_depth_joint" type="fixed">
  <origin xyz="0 0.028 0" rpy="0 0 0" />
  <parent link="kinect_link" />
  <child link="kinect_depth_frame" />
</joint>

<link name="kinect_depth_frame">
  <inertial>
      <mass value="0.0001" />
      <origin xyz="0 0 0" />
      <inertia ixx="0.0001" ixy="0.0" ixz="0.0"
               iyy="0.0001" iyz="0.0" 
               izz="0.0001" />
  </inertial>
</link>

<joint name="depth_optical_joint" type="fixed">
  <origin xyz="0 0 0" rpy="-${pi/2} 0 -${pi/2}" />
  <parent link="kinect_depth_frame" />
  <child link="kinect_depth_optical_frame" />
</joint>

<link name="kinect_depth_optical_frame">
  <inertial>
      <mass value="0.0001" />
      <origin xyz="0 0 0" />
      <inertia ixx="0.0001" ixy="0.0" ixz="0.0"
               iyy="0.0001" iyz="0.0" 
               izz="0.0001" />
  </inertial>
</link>
-->
  <!-- Differential Drive Wheels -->
  <link name="wheel_right">
    <visual>
      <geometry>
        <cylinder length="0.0267" radius="0.0328"/>
      </geometry>
      <origin rpy="1.5707963268 0 0"/>
      <material name="black">
        <color rgba="0 0 0 1"/>
      </material>
    </visual>
  </link>
  <link name="wheel_left">
    <visual>
      <geometry>
        <cylinder length="0.0267" radius="0.0328"/>
      </geometry>
      <origin rpy="-1.5707963268 0 0"/>
      <material name="black">
        <color rgba="0 0 0 1"/>
      </material>
    </visual>
  </link>
  <joint name="wheel_left_joint" type="continuous">
    <parent link="base_link"/>
    <child link="wheel_left"/>
    <axis xyz="0 1 0"/>
    <origin rpy="0 0 0" xyz="0 0.13015 0"/>
  </joint>
  <joint name="wheel_right_joint" type="continuous">
    <parent link="base_link"/>
    <child link="wheel_right"/>
    <axis xyz="0 1 0"/>
    <origin rpy="0 0 0" xyz="0 -0.13015 0"/>
  </joint>
  <!-- Sensor Array -->
  <link name="sonar_left">
    <visual>
      <geometry>
        <box size=".0015 0.0046 0.0021"/>
      </geometry>
    </visual>
  </link>
  <link name="sonar_right">
    <visual>
      <geometry>
        <box size=".0015 0.0046 0.0021"/>
      </geometry>
    </visual>
  </link>
  <link name="ir_left">
    <visual>
      <geometry>
        <box size=".0014 0.0030 0.0013"/>
      </geometry>
    </visual>
  </link>
  <link name="ir_center">
    <visual>
      <geometry>
        <box size=".0014 0.0030 0.0013"/>
      </geometry>
    </visual>
  </link>
  <link name="ir_right">
    <visual>
      <geometry>
        <box size=".0014 0.0030 0.0013"/>
      </geometry>
    </visual>
  </link>
  <joint name="sonar_left_joint" type="fixed">
    <parent link="platform_base"/>
    <child link="sonar_left"/>
    <origin rpy="0 0 0.35" xyz="0.0936 0.0635 0.005"/>
  </joint>
  <joint name="sonar_right_joint" type="fixed">
    <parent link="platform_base"/>
    <child link="sonar_right"/>
    <origin rpy="0 0 -0.35" xyz="0.0936 -0.0635 0.005"/>
  </joint>
  <joint name="ir_left_joint" type="fixed">
    <parent link="platform_base"/>
    <child link="ir_left"/>
    <origin rpy="0 0 0.7" xyz="0.0766 0.125 0.005"/>
  </joint>
  <joint name="ir_center_joint" type="fixed">
    <parent link="platform_base"/>
    <child link="ir_center"/>
    <origin rpy="0 0 0" xyz="0.1023 0 0.005"/>
  </joint>
  <joint name="ir_right_joint" type="fixed">
    <parent link="platform_base"/>
    <child link="ir_right"/>
    <origin rpy="0 0 -0.7" xyz="0.0766 -0.125 0.005"/>
  </joint>
  <link name="sonar_left_depth_frame">
    <inertial>
      <mass value="0.0001"/>
      <origin xyz="0 0 0"/>
      <inertia ixx="0.0001" ixy="0.0" ixz="0.0" iyy="0.0001" iyz="0.0" izz="0.0001"/>
    </inertial>
  </link>
  <link name="sonar_right_depth_frame">
    <inertial>
      <mass value="0.0001"/>
      <origin xyz="0 0 0"/>
      <inertia ixx="0.0001" ixy="0.0" ixz="0.0" iyy="0.0001" iyz="0.0" izz="0.0001"/>
    </inertial>
  </link>
  <link name="ir_left_depth_frame">
    <inertial>
      <mass value="0.0001"/>
      <origin xyz="0 0 0"/>
      <inertia ixx="0.0001" ixy="0.0" ixz="0.0" iyy="0.0001" iyz="0.0" izz="0.0001"/>
    </inertial>
  </link>
  <link name="ir_center_depth_frame">
    <inertial>
      <mass value="0.0001"/>
      <origin xyz="0 0 0"/>
      <inertia ixx="0.0001" ixy="0.0" ixz="0.0" iyy="0.0001" iyz="0.0" izz="0.0001"/>
    </inertial>
  </link>
  <link name="ir_right_depth_frame">
    <inertial>
      <mass value="0.0001"/>
      <origin xyz="0 0 0"/>
      <inertia ixx="0.0001" ixy="0.0" ixz="0.0" iyy="0.0001" iyz="0.0" izz="0.0001"/>
    </inertial>
  </link>
  <joint name="sonar_left_depth_joint" type="fixed">
    <origin rpy="0 0 0" xyz="0 0.015 0"/>
    <parent link="sonar_left"/>
    <child link="sonar_left_depth_frame"/>
  </joint>
  <joint name="sonar_right_depth_joint" type="fixed">
    <origin rpy="0 0 0" xyz="0 0.015 0"/>
    <parent link="sonar_right"/>
    <child link="sonar_right_depth_frame"/>
  </joint>
  <joint name="ir_left_depth_joint" type="fixed">
    <origin rpy="0 0 0" xyz="0 0.015 0"/>
    <parent link="ir_left"/>
    <child link="ir_left_depth_frame"/>
  </joint>
  <joint name="ir_center_depth_joint" type="fixed">
    <origin rpy="0 0 0" xyz="0 0.015 0"/>
    <parent link="ir_center"/>
    <child link="ir_center_depth_frame"/>
  </joint>
  <joint name="ir_right_depth_joint" type="fixed">
    <origin rpy="0 0 0" xyz="0 0.015 0"/>
    <parent link="ir_right"/>
    <child link="ir_right_depth_frame"/>
  </joint>
  <link name="head_unit">
    <visual>
      <geometry>
        <box size="0.0160528 0.1992376 0.119888"/>
      </geometry>
      <material name="black">
        <color rgba="0 0 0 1"/>
      </material>
    </visual>
  </link>
  <joint name="base_link_to_head_unit" type="fixed">
    <parent link="base_link"/>
    <child link="head_unit"/>
    <origin rpy="0 0 0" xyz="0 0 1.2192"/>
  </joint>
  <!-- IMU -->
  <link name="imu">
    <visual>
      <geometry>
        <box size="0.0001 0.0001 0.0001"/>
      </geometry>
      <material name="green">
        <color rgba="0 192 0 1"/>
      </material>
    </visual>
  </link>
  <joint name="head_unit_to_imu" type="fixed">
    <parent link="head_unit"/>
    <child link="imu"/>
    <origin rpy="0 0 0" xyz="0 0 0"/>
  </joint>
  <!-- GPS UNIT -->
  <link name="fix">
    <visual>
      <geometry>
        <box size="0.0001 0.0001 0.0001"/>
      </geometry>
      <material name="blue">
        <color rgba="0 0 192 1"/>
      </material>
    </visual>
  </link>
  <joint name="head_unit_to_fix" type="fixed">
    <parent link="head_unit"/>
    <child link="fix"/>
    <origin rpy="0 0 0" xyz="0 0 0"/>
  </joint>
  <link name="depth_camera">
    <visual>
      <geometry>
        <box size="0.1 0.1 0.1"/>
      </geometry>
      <material name="blue">
        <color rgba="0 0 192 1"/>
      </material>
    </visual>
  </link>
  <joint name="head_unit_to_depth_camera" type="fixed">
    <parent link="head_unit"/>
    <child link="depth_camera"/>
    <origin rpy="0 0 0" xyz="0 0.24 0"/>
  </joint>
  <link name="fisheye_camera">
    <visual>
      <geometry>
        <box size="0.1 0.1 0.1"/>
      </geometry>
      <material name="red">
        <color rgba="192 0 0 1"/>
      </material>
    </visual>
  </link>
  <joint name="head_unit_to_fisheye_camera" type="fixed">
    <parent link="head_unit"/>
    <child link="fisheye_camera"/>
    <origin rpy="0 0 0" xyz="0 0.4 0"/>
  </joint>
  <!--
<node pkg="tf" type="static_transform_publisher" name="device_to_depth_cam" args="0 0 0 0 0.24 0 device depth_camera 10"/>
<node pkg="tf" type="static_transform_publisher" name="fisheye_to_depth_cam" args="0 -0.05 0 0 0 0 depth_camera fisheye_camera 10"/>
-->
</robot>

